<?xml version="1.0" encoding="UTF-8"?>
<!-- Generated by org.testng.reporters.JUnitReportReporter -->
<testsuite hostname="DESKTOP-J5DL5AU" failures="2" tests="9" name="retrysingletest.RetryOnlyFailedTests" time="0.308" errors="0" timestamp="2024-07-03T08:19:42 IST" skipped="6">
  <testcase classname="retrysingletest.RetryOnlyFailedTests" name="test1" time="0.030">
    <skipped/>
  </testcase> <!-- test1 -->
  <system-out/>
  <testcase classname="retrysingletest.RetryOnlyFailedTests" name="test1" time="0.019">
    <skipped/>
  </testcase> <!-- test1 -->
  <system-out/>
  <testcase classname="retrysingletest.RetryOnlyFailedTests" name="test2" time="0.007">
    <skipped/>
  </testcase> <!-- test2 -->
  <system-out/>
  <testcase classname="retrysingletest.RetryOnlyFailedTests" name="test3" time="0.002"/>
  <system-out/>
  <testcase classname="retrysingletest.RetryOnlyFailedTests" name="test1" time="0.226">
    <skipped/>
  </testcase> <!-- test1 -->
  <system-out/>
  <testcase classname="retrysingletest.RetryOnlyFailedTests" name="test2" time="0.006">
    <skipped/>
  </testcase> <!-- test2 -->
  <system-out/>
  <testcase classname="retrysingletest.RetryOnlyFailedTests" name="test2" time="0.007">
    <failure message="Addition Problem! 2+2 must be 4!
 expected [3] but found [4]" type="java.lang.AssertionError">
      <![CDATA[java.lang.AssertionError: Addition Problem! 2+2 must be 4!
 expected [3] but found [4]
at org.testng.Assert.fail(Assert.java:110)
at org.testng.Assert.failNotEquals(Assert.java:1577)
at org.testng.Assert.assertEqualsImpl(Assert.java:149)
at org.testng.Assert.assertEquals(Assert.java:131)
at org.testng.Assert.assertEquals(Assert.java:1418)
at org.testng.Assert.assertEquals(Assert.java:1382)
at retrysingletest.RetryOnlyFailedTests.test2(RetryOnlyFailedTests.java:17)
at java.base/jdk.internal.reflect.NativeMethodAccessorImpl.invoke0(Native Method)
at java.base/jdk.internal.reflect.NativeMethodAccessorImpl.invoke(NativeMethodAccessorImpl.java:64)
at java.base/jdk.internal.reflect.DelegatingMethodAccessorImpl.invoke(DelegatingMethodAccessorImpl.java:43)
at java.base/java.lang.reflect.Method.invoke(Method.java:564)
at org.testng.internal.invokers.MethodInvocationHelper.invokeMethod(MethodInvocationHelper.java:139)
at org.testng.internal.invokers.TestInvoker.invokeMethod(TestInvoker.java:677)
at org.testng.internal.invokers.TestInvoker.retryFailed(TestInvoker.java:263)
at org.testng.internal.invokers.MethodRunner.runInSequence(MethodRunner.java:62)
at org.testng.internal.invokers.TestInvoker$MethodInvocationAgent.invoke(TestInvoker.java:969)
at org.testng.internal.invokers.TestInvoker.invokeTestMethods(TestInvoker.java:194)
at org.testng.internal.invokers.TestMethodWorker.invokeTestMethods(TestMethodWorker.java:148)
at org.testng.internal.invokers.TestMethodWorker.run(TestMethodWorker.java:128)
at java.base/java.util.concurrent.ThreadPoolExecutor.runWorker(ThreadPoolExecutor.java:1130)
at java.base/java.util.concurrent.ThreadPoolExecutor$Worker.run(ThreadPoolExecutor.java:630)
at java.base/java.lang.Thread.run(Thread.java:832)
]]>
    </failure>
  </testcase> <!-- test2 -->
  <system-out/>
  <testcase classname="retrysingletest.RetryOnlyFailedTests" name="test2" time="0.003">
    <skipped/>
  </testcase> <!-- test2 -->
  <system-out/>
  <testcase classname="retrysingletest.RetryOnlyFailedTests" name="test1" time="0.008">
    <failure message="Addition Problem! 2+2 must be 4!
 expected [5] but found [4]" type="java.lang.AssertionError">
      <![CDATA[java.lang.AssertionError: Addition Problem! 2+2 must be 4!
 expected [5] but found [4]
at org.testng.Assert.fail(Assert.java:110)
at org.testng.Assert.failNotEquals(Assert.java:1577)
at org.testng.Assert.assertEqualsImpl(Assert.java:149)
at org.testng.Assert.assertEquals(Assert.java:131)
at org.testng.Assert.assertEquals(Assert.java:1418)
at org.testng.Assert.assertEquals(Assert.java:1382)
at retrysingletest.RetryOnlyFailedTests.test1(RetryOnlyFailedTests.java:11)
at java.base/jdk.internal.reflect.NativeMethodAccessorImpl.invoke0(Native Method)
at java.base/jdk.internal.reflect.NativeMethodAccessorImpl.invoke(NativeMethodAccessorImpl.java:64)
at java.base/jdk.internal.reflect.DelegatingMethodAccessorImpl.invoke(DelegatingMethodAccessorImpl.java:43)
at java.base/java.lang.reflect.Method.invoke(Method.java:564)
at org.testng.internal.invokers.MethodInvocationHelper.invokeMethod(MethodInvocationHelper.java:139)
at org.testng.internal.invokers.TestInvoker.invokeMethod(TestInvoker.java:677)
at org.testng.internal.invokers.TestInvoker.retryFailed(TestInvoker.java:263)
at org.testng.internal.invokers.MethodRunner.runInSequence(MethodRunner.java:62)
at org.testng.internal.invokers.TestInvoker$MethodInvocationAgent.invoke(TestInvoker.java:969)
at org.testng.internal.invokers.TestInvoker.invokeTestMethods(TestInvoker.java:194)
at org.testng.internal.invokers.TestMethodWorker.invokeTestMethods(TestMethodWorker.java:148)
at org.testng.internal.invokers.TestMethodWorker.run(TestMethodWorker.java:128)
at java.base/java.util.concurrent.ThreadPoolExecutor.runWorker(ThreadPoolExecutor.java:1130)
at java.base/java.util.concurrent.ThreadPoolExecutor$Worker.run(ThreadPoolExecutor.java:630)
at java.base/java.lang.Thread.run(Thread.java:832)
]]>
    </failure>
  </testcase> <!-- test1 -->
  <system-out/>
</testsuite> <!-- retrysingletest.RetryOnlyFailedTests -->
